Workbook

Sheet Resumo
A1: RESUMO — POSIÇÃO DE ESTOQUE
A2: Gerado em 02/10/2026, 13:56:55 • Todos os valores são fórmulas ligadas à aba Estoque
A4: 1. VISÃO GERAL
A5: GRUPO | B5: ITENS | C5: SALDO FOCCO | D5: SALDO FULL | E5: RESERVAS | F5: DISPONÍVEL | G5: PESO TOTAL (t) | H5: PESO RESERV. (t) | I5: VALOR ESTOQUE | J5: VALOR RESERVADO | K5: % RESERV.
A6: EM LINHA | B6: =COUNTIF(Estoque!$H$5:$H$789,$A6) | C6: =SUMIF(Estoque!$H$5:$H$789,$A6,Estoque!$J$5:$J$789) | D6: =SUMIF(Estoque!$H$5:$H$789,$A6,Estoque!$K$5:$K$789) | E6: =SUMIF(Estoque!$H$5:$H$789,$A6,Estoque!$L$5:$L$789) | F6: =SUMIF(Estoque!$H$5:$H$789,$A6,Estoque!$M$5:$M$789) | G6: =SUMIF(Estoque!$H$5:$H$789,$A6,Estoque!$O$5:$O$789)/1000 | H6: =SUMIF(Estoque!$H$5:$H$789,$A6,Estoque!$P$5:$P$789)/1000 | I6: =SUMIF(Estoque!$H$5:$H$789,$A6,Estoque!$R$5:$R$789) | J6: =SUMIF(Estoque!$H$5:$H$789,$A6,Estoque!$S$5:$S$789) | K6: =IF(C6=0,0,E6/C6)
A7: FORA DE LINHA | B7: =COUNTIF(Estoque!$H$5:$H$789,$A7) | C7: =SUMIF(Estoque!$H$5:$H$789,$A7,Estoque!$J$5:$J$789) | D7: =SUMIF(Estoque!$H$5:$H$789,$A7,Estoque!$K$5:$K$789) | E7: =SUMIF(Estoque!$H$5:$H$789,$A7,Estoque!$L$5:$L$789) | F7: =SUMIF(Estoque!$H$5:$H$789,$A7,Estoque!$M$5:$M$789) | G7: =SUMIF(Estoque!$H$5:$H$789,$A7,Estoque!$O$5:$O$789)/1000 | H7: =SUMIF(Estoque!$H$5:$H$789,$A7,Estoque!$P$5:$P$789)/1000 | I7: =SUMIF(Estoque!$H$5:$H$789,$A7,Estoque!$R$5:$R$789) | J7: =SUMIF(Estoque!$H$5:$H$789,$A7,Estoque!$S$5:$S$789) | K7: =IF(C7=0,0,E7/C7)
A8: NÃO CADASTRADO | B8: =COUNTIF(Estoque!$H$5:$H$789,$A8) | C8: =SUMIF(Estoque!$H$5:$H$789,$A8,Estoque!$J$5:$J$789) | D8: =SUMIF(Estoque!$H$5:$H$789,$A8,Estoque!$K$5:$K$789) | E8: =SUMIF(Estoque!$H$5:$H$789,$A8,Estoque!$L$5:$L$789) | F8: =SUMIF(Estoque!$H$5:$H$789,$A8,Estoque!$M$5:$M$789) | G8: =SUMIF(Estoque!$H$5:$H$789,$A8,Estoque!$O$5:$O$789)/1000 | H8: =SUMIF(Estoque!$H$5:$H$789,$A8,Estoque!$P$5:$P$789)/1000 | I8: =SUMIF(Estoque!$H$5:$H$789,$A8,Estoque!$R$5:$R$789) | J8: =SUMIF(Estoque!$H$5:$H$789,$A8,Estoque!$S$5:$S$789) | K8: =IF(C8=0,0,E8/C8)
A9: TOTAL | B9: =SUM(B6:B8) | C9: =SUM(C6:C8) | D9: =SUM(D6:D8) | E9: =SUM(E6:E8) | F9: =SUM(F6:F8) | G9: =SUM(G6:G8) | H9: =SUM(H6:H8) | I9: =SUM(I6:I8) | J9: =SUM(J6:J8) | K9: =IF(C9=0,0,E9/C9)
A12: 2. FORA DE LINHA POR ORIGEM
A13: GRUPO | B13: ITENS | C13: SALDO FOCCO | D13: SALDO FULL | E13: RESERVAS | F13: DISPONÍVEL | G13: PESO TOTAL (t) | H13: PESO RESERV. (t) | I13: VALOR ESTOQUE | J13: VALOR RESERVADO | K13: % RESERV.
A14: SO GERSON | B14: =COUNTIF(Estoque!$I$5:$I$789,$A14) | C14: =SUMIF(Estoque!$I$5:$I$789,$A14,Estoque!$J$5:$J$789) | D14: =SUMIF(Estoque!$I$5:$I$789,$A14,Estoque!$K$5:$K$789) | E14: =SUMIF(Estoque!$I$5:$I$789,$A14,Estoque!$L$5:$L$789) | F14: =SUMIF(Estoque!$I$5:$I$789,$A14,Estoque!$M$5:$M$789) | G14: =SUMIF(Estoque!$I$5:$I$789,$A14,Estoque!$O$5:$O$789)/1000 | H14: =SUMIF(Estoque!$I$5:$I$789,$A14,Estoque!$P$5:$P$789)/1000 | I14: =SUMIF(Estoque!$I$5:$I$789,$A14,Estoque!$R$5:$R$789) | J14: =SUMIF(Estoque!$I$5:$I$789,$A14,Estoque!$S$5:$S$789) | K14: =IF(C14=0,0,E14/C14)
A15: SO ELIANE | B15: =COUNTIF(Estoque!$I$5:$I$789,$A15) | C15: =SUMIF(Estoque!$I$5:$I$789,$A15,Estoque!$J$5:$J$789) | D15: =SUMIF(Estoque!$I$5:$I$789,$A15,Estoque!$K$5:$K$789) | E15: =SUMIF(Estoque!$I$5:$I$789,$A15,Estoque!$L$5:$L$789) | F15: =SUMIF(Estoque!$I$5:$I$789,$A15,Estoque!$M$5:$M$789) | G15: =SUMIF(Estoque!$I$5:$I$789,$A15,Estoque!$O$5:$O$789)/1000 | H15: =SUMIF(Estoque!$I$5:$I$789,$A15,Estoque!$P$5:$P$789)/1000 | I15: =SUMIF(Estoque!$I$5:$I$789,$A15,Estoque!$R$5:$R$789) | J15: =SUMIF(Estoque!$I$5:$I$789,$A15,Estoque!$S$5:$S$789) | K15: =IF(C15=0,0,E15/C15)
A16: EM AMBAS | B16: =COUNTIF(Estoque!$I$5:$I$789,$A16) | C16: =SUMIF(Estoque!$I$5:$I$789,$A16,Estoque!$J$5:$J$789) | D16: =SUMIF(Estoque!$I$5:$I$789,$A16,Estoque!$K$5:$K$789) | E16: =SUMIF(Estoque!$I$5:$I$789,$A16,Estoque!$L$5:$L$789) | F16: =SUMIF(Estoque!$I$5:$I$789,$A16,Estoque!$M$5:$M$789) | G16: =SUMIF(Estoque!$I$5:$I$789,$A16,Estoque!$O$5:$O$789)/1000 | H16: =SUMIF(Estoque!$I$5:$I$789,$A16,Estoque!$P$5:$P$789)/1000 | I16: =SUMIF(Estoque!$I$5:$I$789,$A16,Estoque!$R$5:$R$789) | J16: =SUMIF(Estoque!$I$5:$I$789,$A16,Estoque!$S$5:$S$789) | K16: =IF(C16=0,0,E16/C16)
A17: TOTAL | B17: =SUM(B14:B16) | C17: =SUM(C14:C16) | D17: =SUM(D14:D16) | E17: =SUM(E14:E16) | F17: =SUM(F14:F16) | G17: =SUM(G14:G16) | H17: =SUM(H14:H16) | I17: =SUM(I14:I16) | J17: =SUM(J14:J16) | K17: =IF(C17=0,0,E17/C17)
A20: 3. POR CATEGORIA
A21: GRUPO | B21: ITENS | C21: SALDO FOCCO | D21: SALDO FULL | E21: RESERVAS | F21: DISPONÍVEL | G21: PESO TOTAL (t) | H21: PESO RESERV. (t) | I21: VALOR ESTOQUE | J21: VALOR RESERVADO | K21: % RESERV.
A22: EMBALAGEM JOGO DE PES | B22: =COUNTIF(Estoque!$F$5:$F$789,$A22) | C22: =SUMIF(Estoque!$F$5:$F$789,$A22,Estoque!$J$5:$J$789) | D22: =SUMIF(Estoque!$F$5:$F$789,$A22,Estoque!$K$5:$K$789) | E22: =SUMIF(Estoque!$F$5:$F$789,$A22,Estoque!$L$5:$L$789) | F22: =SUMIF(Estoque!$F$5:$F$789,$A22,Estoque!$M$5:$M$789) | G22: =SUMIF(Estoque!$F$5:$F$789,$A22,Estoque!$O$5:$O$789)/1000 | H22: =SUMIF(Estoque!$F$5:$F$789,$A22,Estoque!$P$5:$P$789)/1000 | I22: =SUMIF(Estoque!$F$5:$F$789,$A22,Estoque!$R$5:$R$789) | J22: =SUMIF(Estoque!$F$5:$F$789,$A22,Estoque!$S$5:$S$789) | K22: =IF(C22=0,0,E22/C22)
A23: UNIDADE DE COMPLEMENTOS | B23: =COUNTIF(Estoque!$F$5:$F$789,$A23) | C23: =SUMIF(Estoque!$F$5:$F$789,$A23,Estoque!$J$5:$J$789) | D23: =SUMIF(Estoque!$F$5:$F$789,$A23,Estoque!$K$5:$K$789) | E23: =SUMIF(Estoque!$F$5:$F$789,$A23,Estoque!$L$5:$L$789) | F23: =SUMIF(Estoque!$F$5:$F$789,$A23,Estoque!$M$5:$M$789) | G23: =SUMIF(Estoque!$F$5:$F$789,$A23,Estoque!$O$5:$O$789)/1000 | H23: =SUMIF(Estoque!$F$5:$F$789,$A23,Estoque!$P$5:$P$789)/1000 | I23: =SUMIF(Estoque!$F$5:$F$789,$A23,Estoque!$R$5:$R$789) | J23: =SUMIF(Estoque!$F$5:$F$789,$A23,Estoque!$S$5:$S$789) | K23: =IF(C23=0,0,E23/C23)
A24: UNIDADE DE SALAS | B24: =COUNTIF(Estoque!$F$5:$F$789,$A24) | C24: =SUMIF(Estoque!$F$5:$F$789,$A24,Estoque!$J$5:$J$789) | D24: =SUMIF(Estoque!$F$5:$F$789,$A24,Estoque!$K$5:$K$789) | E24: =SUMIF(Estoque!$F$5:$F$789,$A24,Estoque!$L$5:$L$789) | F24: =SUMIF(Estoque!$F$5:$F$789,$A24,Estoque!$M$5:$M$789) | G24: =SUMIF(Estoque!$F$5:$F$789,$A24,Estoque!$O$5:$O$789)/1000 | H24: =SUMIF(Estoque!$F$5:$F$789,$A24,Estoque!$P$5:$P$789)/1000 | I24: =SUMIF(Estoque!$F$5:$F$789,$A24,Estoque!$R$5:$R$789) | J24: =SUMIF(Estoque!$F$5:$F$789,$A24,Estoque!$S$5:$S$789) | K24: =IF(C24=0,0,E24/C24)
A25: UNIDADE GUARDA ROUPAS | B25: =COUNTIF(Estoque!$F$5:$F$789,$A25) | C25: =SUMIF(Estoque!$F$5:$F$789,$A25,Estoque!$J$5:$J$789) | D25: =SUMIF(Estoque!$F$5:$F$789,$A25,Estoque!$K$5:$K$789) | E25: =SUMIF(Estoque!$F$5:$F$789,$A25,Estoque!$L$5:$L$789) | F25: =SUMIF(Estoque!$F$5:$F$789,$A25,Estoque!$M$5:$M$789) | G25: =SUMIF(Estoque!$F$5:$F$789,$A25,Estoque!$O$5:$O$789)/1000 | H25: =SUMIF(Estoque!$F$5:$F$789,$A25,Estoque!$P$5:$P$789)/1000 | I25: =SUMIF(Estoque!$F$5:$F$789,$A25,Estoque!$R$5:$R$789) | J25: =SUMIF(Estoque!$F$5:$F$789,$A25,Estoque!$S$5:$S$789) | K25: =IF(C25=0,0,E25/C25)
A26: VIDRO/ESPELHO | B26: =COUNTIF(Estoque!$F$5:$F$789,$A26) | C26: =SUMIF(Estoque!$F$5:$F$789,$A26,Estoque!$J$5:$J$789) | D26: =SUMIF(Estoque!$F$5:$F$789,$A26,Estoque!$K$5:$K$789) | E26: =SUMIF(Estoque!$F$5:$F$789,$A26,Estoque!$L$5:$L$789) | F26: =SUMIF(Estoque!$F$5:$F$789,$A26,Estoque!$M$5:$M$789) | G26: =SUMIF(Estoque!$F$5:$F$789,$A26,Estoque!$O$5:$O$789)/1000 | H26: =SUMIF(Estoque!$F$5:$F$789,$A26,Estoque!$P$5:$P$789)/1000 | I26: =SUMIF(Estoque!$F$5:$F$789,$A26,Estoque!$R$5:$R$789) | J26: =SUMIF(Estoque!$F$5:$F$789,$A26,Estoque!$S$5:$S$789) | K26: =IF(C26=0,0,E26/C26)
A27: TOTAL | B27: =SUM(B22:B26) | C27: =SUM(C22:C26) | D27: =SUM(D22:D26) | E27: =SUM(E22:E26) | F27: =SUM(F22:F26) | G27: =SUM(G22:G26) | H27: =SUM(H22:H26) | I27: =SUM(I22:I26) | J27: =SUM(J22:J26) | K27: =IF(C27=0,0,E27/C27)
A30: Legenda: azul = dado importado • verde = buscado em outra aba • preto = cálculo

Sheet Estoque
A1: POSIÇÃO DE ESTOQUE — EM LINHA x FORA DE LINHA
A2: Base: Estoque Focco (785 itens) • Gerado em 02/10/2026, 13:56:55 • Totais da linha 3 respeitam filtros
B3: =SUBTOTAL(103,B5:B789) | C3: TOTAL (FILTRADO) | J3: =SUBTOTAL(109,J5:J789) | K3: =SUBTOTAL(109,K5:K789) | L3: =SUBTOTAL(109,L5:L789) | M3: =SUBTOTAL(109,M5:M789) | O3: =SUBTOTAL(109,O5:O789) | P3: =SUBTOTAL(109,P5:P789) | R3: =SUBTOTAL(109,R5:R789) | S3: =SUBTOTAL(109,S5:S789) | T3: =IF(J3=0,0,L3/J3) | W3: =SUBTOTAL(109,W5:W789) | X3: =SUBTOTAL(109,X5:X789)
A4: CHAVE | B4: ITEM | C4: DESCRIÇÃO | D4: MÁSCARA (COR) | E4: REF. TEK | F4: CATEGORIA | G4: CLASSIF. N2 | H4: SITUAÇÃO | I4: ORIGEM | J4: SALDO FOCCO | K4: SALDO FULL | L4: RESERVAS | M4: DISPONÍVEL | N4: PESO UN. (kg) | O4: PESO TOTAL (kg) | P4: PESO RESERV. (kg) | Q4: CUSTO MÉDIO | R4: VALOR ESTOQUE | S4: VALOR RESERVADO | T4: % RESERV. | U4: PALETE (FORRO) | V4: UND / PALETE | W4: QTD PALETES | X4: PALETES DISP.
A5: =B5&"."&IFERROR(MID(D5,FIND("(",D5)+1,FIND(")",D5)-FIND("(",D5)-1),"") -> 84911.31290 | B5: 84911 | C5: VOL CX PAINEL CAMA CASAL 1,40 LOOP 2025 1,535X0,730X0,117 | D5: (31290)FRASSINO#CORANO BEGE | E5: 96437 | F5: UNIDADE DE COMPLEMENTOS | G5: VOLUME | H5: =IFERROR(INDEX(Linha!$B$5:$B$788,MATCH(A5,Linha!$A$5:$A$788,0)),"NÃO CADASTRADO") | I5: =IFERROR(INDEX(Linha!$C$5:$C$788,MATCH(A5,Linha!$A$5:$A$788,0)),"-") | J5: 0 | K5: =IFERROR(INDEX(Linha!$D$5:$D$788,MATCH(A5,Linha!$A$5:$A$788,0))*1,0) | L5: =SUMIFS(Reservas!$K$5:$K$3669,Reservas!$A$5:$A$3669,A5) | M5: =J5-L5 | N5: 34.222 | O5: =J5*N5 | P5: =L5*N5 | Q5: 137.8332 | R5: =J5*Q5 | S5: =L5*Q5 | T5: =IF(J5=0,0,L5/J5) | U5: =IFERROR(INDEX(Paletes!$C$5:$C$393,MATCH(B5,Paletes!$A$5:$A$393,0)),"SEM CADASTRO") | V5: =IFERROR(INDEX(Paletes!$D$5:$D$393,MATCH(B5,Paletes!$A$5:$A$393,0)),0) | W5: =IF(V5=0,0,J5/V5) | X5: =IF(V5=0,0,MAX(M5,0)/V5)
A6: =B6&"."&IFERROR(MID(D6,FIND("(",D6)+1,FIND(")",D6)-FIND("(",D6)-1),"") -> 84901.31285 | B6: 84901 | C6: VOL CX BARRA CAMA CASAL 1,40 LOOP/LEDER 2025 2,018X0,357X0,105 | D6: (31285)FRASSINO | E6: 96436 | F6: UNIDADE DE COMPLEMENTOS | G6: VOLUME | H6: =IFERROR(INDEX(Linha!$B$5:$B$788,MATCH(A6,Linha!$A$5:$A$788,0)),"NÃO CADASTRADO") | I6: =IFERROR(INDEX(Linha!$C$5:$C$788,MATCH(A6,Linha!$A$5:$A$788,0)),"-") | J6: 78 | K6: =IFERROR(INDEX(Linha!$D$5:$D$788,MATCH(A6,Linha!$A$5:$A$788,0))*1,0) | L6: =SUMIFS(Reservas!$K$5:$K$3669,Reservas!$A$5:$A$3669,A6) | M6: =J6-L6 | N6: 36.66 | O6: =J6*N6 | P6: =L6*N6 | Q6: 158.90195 | R6: =J6*Q6 | S6: =L6*Q6 | T6: =IF(J6=0,0,L6/J6) | U6: =IFERROR(INDEX(Paletes!$C$5:$C$393,MATCH(B6,Paletes!$A$5:$A$393,0)),"SEM CADASTRO") | V6: =IFERROR(INDEX(Paletes!$D$5:$D$393,MATCH(B6,Paletes!$A$5:$A$393,0)),0) | W6: =IF(V6=0,0,J6/V6) | X6: =IF(V6=0,0,MAX(M6,0)/V6)
A7: =B7&"."&IFERROR(MID(D7,FIND("(",D7)+1,FIND(")",D7)-FIND("(",D7)-1),"") -> 84966.89604 | B7: 84966 | C7: VOL CX LAT/GAV COMODA LOOP 2025 EXP 0,880X0,495X0,197 | D7: (89604)AMENDOA CLEAN#C/LOGO | E7: 97476 | F7: UNIDADE DE COMPLEMENTOS | G7: VOLUME | H7: =IFERROR(INDEX(Linha!$B$5:$B$788,MATCH(A7,Linha!$A$5:$A$788,0)),"NÃO CADASTRADO") | I7: =IFERROR(INDEX(Linha!$C$5:$C$788,MATCH(A7,Linha!$A$5:$A$788,0)),"-") | J7: 6 | K7: =IFERROR(INDEX(Linha!$D$5:$D$788,MATCH(A7,Linha!$A$5:$A$788,0))*1,0) | L7: =SUMIFS(Reservas!$K$5:$K$3669,Reservas!$A$5:$A$3669,A7) | M7: =J7-L7 | N7: 35.1 | O7: =J7*N7 | P7: =L7*N7 | Q7: 188.8043 | R7: =J7*Q7 | S7: =L7*Q7 | T7: =IF(J7=0,0,L7/J7) | U7: =IFERROR(INDEX(Paletes!$C$5:$C$393,MATCH(B7,Paletes!$A$5:$A$393,0)),"SEM CADASTRO") | V7: =IFERROR(INDEX(Paletes!$D$5:$D$393,MATCH(B7,Paletes!$A$5:$A$393,0)),0) | W7: =IF(V7=0,0,J7/V7) | X7: =IF(V7=0,0,MAX(M7,0)/V7)
A8: =B8&"."&IFERROR(MID(D8,FIND("(",D8)+1,FIND(")",D8)-FIND("(",D8)-1),"") -> 86324.69485 | B8: 86324 | C8: VOL CX GR 2PTS QUADRIX/PAMPULHA 1 PORTA MDF 2,190X0,750X0,055 | D8: (69485)FRASSINO/OFF WHITE | E8: 100435 | F8: UNIDADE GUARDA ROUPAS | G8: VOLUME | H8: =IFERROR(INDEX(Linha!$B$5:$B$788,MATCH(A8,Linha!$A$5:$A$788,0)),"NÃO CADASTRADO") | I8: =IFERROR(INDEX(Linha!$C$5:$C$788,MATCH(A8,Linha!$A$5:$A$788,0)),"-") | J8: 0 | K8: =IFERROR(INDEX(Linha!$D$5:$D$788,MATCH(A8,Linha!$A$5:$A$788,0))*1,0) | L8: =SUMIFS(Reservas!$K$5:$K$3669,Reservas!$A$5:$A$3669,A8) | M8: =J8-L8 | N8: 15.161 | O8: =J8*N8 | P8: =L8*N8 | Q8: 76.736099 | R8: =J8*Q8 | S8: =L8*Q8 | T8: =IF(J8=0,0,L8/J8) | U8: =IFERROR(INDEX(Paletes!$C$5:$C$393,MATCH(B8,Paletes!$A$5:$A$393,0)),"SEM CADASTRO") | V8: =IFERROR(INDEX(Paletes!$D$5:$D$393,MATCH(B8,Paletes!$A$5:$A$393,0)),0) | W8: =IF(V8=0,0,J8/V8) | X8: =IF(V8=0,0,MAX(M8,0)/V8)
A9: =B9&"."&IFERROR(MID(D9,FIND("(",D9)+1,FIND(")",D9)-FIND("(",D9)-1),"") -> 102.12218 | B9: 102 | C9: VOL CX GR 6 PTS ZEUS PLUS PTS/COSTAS 1,950X0,600X0,067 | D9: (12218)AMENDOA CLEAN | E9: 39131 | F9: UNIDADE GUARDA ROUPAS | G9: VOLUME | H9: =IFERROR(INDEX(Linha!$B$5:$B$788,MATCH(A9,Linha!$A$5:$A$788,0)),"NÃO CADASTRADO") | I9: =IFERROR(INDEX(Linha!$C$5:$C$788,MATCH(A9,Linha!$A$5:$A$788,0)),"-") | J9: 428 | K9: =IFERROR(INDEX(Linha!$D$5:$D$788,MATCH(A9,Linha!$A$5:$A$788,0))*1,0) | L9: =SUMIFS(Reservas!$K$5:$K$3669,Reservas!$A$5:$A$3669,A9) | M9: =J9-L9 | N9: 38.61 | O9: =J9*N9 | P9: =L9*N9 | Q9: 133.16089 | R9: =J9*Q9 | S9: =L9*Q9 | T9: =IF(J9=0,0,L9/J9) | U9: =IFERROR(INDEX(Paletes!$C$5:$C$393,MATCH(B9,Paletes!$A$5:$A$393,0)),"SEM CADASTRO") | V9: =IFERROR(INDEX(Paletes!$D$5:$D$393,MATCH(B9,Paletes!$A$5:$A$393,0)),0) | W9: =IF(V9=0,0,J9/V9) | X9: =IF(V9=0,0,MAX(M9,0)/V9)
A10: =B10&"."&IFERROR(MID(D10,FIND("(",D10)+1,FIND(")",D10)-FIND("(",D10)-1),"") -> 102.64910 | B10: 102 | C10: VOL CX GR 6 PTS ZEUS PLUS PTS/COSTAS 1,950X0,600X0,067 | D10: (64910)IMBUIA CLEAN | E10: 39131 | F10: UNIDADE GUARDA ROUPAS | G10: VOLUME | H10: =IFERROR(INDEX(Linha!$B$5:$B$788,MATCH(A10,Linha!$A$5:$A$788,0)),"NÃO CADASTRADO") | I10: =IFERROR(INDEX(Linha!$C$5:$C$788,MATCH(A10,Linha!$A$5:$A$788,0)),"-") | J10: 1 | K10: =IFERROR(INDEX(Linha!$D$5:$D$788,MATCH(A10,Linha!$A$5:$A$788,0))*1,0) | L10: =SUMIFS(Reservas!$K$5:$K$3669,Reservas!$A$5:$A$3669,A10) | M10: =J10-L10 | N10: 38.61 | O10: =J10*N10 | P10: =L10*N10 | Q10: 126.2401 | R10: =J10*Q10 | S10: =L10*Q10 | T10: =IF(J10=0,0,L10/J10) | U10: =IFERROR(INDEX(Paletes!$C$5:$C$393,MATCH(B10,Paletes!$A$5:$A$393,0)),"SEM CADASTRO") | V10: =IFERROR(INDEX(Paletes!$D$5:$D$393,MATCH(B10,Paletes!$A$5:$A$393,0)),0) | W10: =IF(V10=0,0,J10/V10) | X10: =IF(V10=0,0,MAX(M10,0)/V10)
A11: =B11&"."&IFERROR(MID(D11,FIND("(",D11)+1,FIND(")",D11)-FIND("(",D11)-1),"") -> 2163.15691 | B11: 2163 | C11: VOL CX PES ATHENAS CASAL PLUS 1,625X0,200X0,100 | D11: (15691)AMENDOA CLEAN | E11: 40580 | F11: UNIDADE DE COMPLEMENTOS | G11: VOLUME | H11: =IFERROR(INDEX(Linha!$B$5:$B$788,MATCH(A11,Linha!$A$5:$A$788,0)),"NÃO CADASTRADO") | I11: =IFERROR(INDEX(Linha!$C$5:$C$788,MATCH(A11,Linha!$A$5:$A$788,0)),"-") | J11: 771 | K11: =IFERROR(INDEX(Linha!$D$5:$D$788,MATCH(A11,Linha!$A$5:$A$788,0))*1,0) | L11: =SUMIFS(Reservas!$K$5:$K$3669,Reservas!$A$5:$A$3669,A11) | M11: =J11-L11 | N11: 17.94 | O11: =J11*N11 | P11: =L11*N11 | Q11: 81.747218 | R11: =J11*Q11 | S11: =L11*Q11 | T11: =IF(J11=0,0,L11/J11) | U11: =IFERROR(INDEX(Paletes!$C$5:$C$393,MATCH(B11,Paletes!$A$5:$A$393,0)),"SEM CADASTRO") | V11: =IFERROR(INDEX(Paletes!$D$5:$D$393,MATCH(B11,Paletes!$A$5:$A$393,0)),0) | W11: =IF(V11=0,0,J11/V11) | X11: =IF(V11=0,0,MAX(M11,0)/V11)
A12: =B12&"."&IFERROR(MID(D12,FIND("(",D12)+1,FIND(")",D12)-FIND("(",D12)-1),"") -> 73145.23982 | B12: 73145 | C12: VOL CX PES ATHENAS SOLT 0,90 PLUS 1,210X0,275X0,100 | D12: (23982)FRASSINO | E12: 40598 | F12: UNIDADE DE COMPLEMENTOS | G12: VOLUME | H12: =IFERROR(INDEX(Linha!$B$5:$B$788,MATCH(A12,Linha!$A$5:$A$788,0)),"NÃO CADASTRADO") | I12: =IFERROR(INDEX(Linha!$C$5:$C$788,MATCH(A12,Linha!$A$5:$A$788,0)),"-") | J12: 21 | K12: =IFERROR(INDEX(Linha!$D$5:$D$788,MATCH(A12,Linha!$A$5:$A$788,0))*1,0) | L12: =SUMIFS(Reservas!$K$5:$K$3669,Reservas!$A$5:$A$3669,A12) | M12: =J12-L12 | N12: 17.16 | O12: =J12*N12 | P12: =L12*N12 | Q12: 84.92713 | R12: =J12*Q12 | S12: =L12*Q12 | T12: =IF(J12=0,0,L12/J12) | U12: =IFERROR(INDEX(Paletes!$C$5:$C$393,MATCH(B12,Paletes!$A$5:$A$393,0)),"SEM CADASTRO") | V12: =IFERROR(INDEX(Paletes!$D$5:$D$393,MATCH(B12,Paletes!$A$5:$A$393,0)),0) | W12: =IF(V12=0,0,J12/V12) | X12: =IF(V12=0,0,MAX(M12,0)/V12)
A13: =B13&"."&IFERROR(MID(D13,FIND("(",D13)+1,FIND(")",D13)-FIND("(",D13)-1),"") -> 156.15497 | B13: 156 | C13: VOL CX MESA DE CABECEIRA C/03 GAV MAGGIORE NEW 0,700X0,390X0,171 | D13: (15497)AMENDOA CLEAN/OFF WH | E13: 41606 | F13: UNIDADE DE COMPLEMENTOS | G13: VOLUME | H13: =IFERROR(INDEX(Linha!$B$5:$B$788,MATCH(A13,Linha!$A$5:$A$788,0)),"NÃO CADASTRADO") | I13: =IFERROR(INDEX(Linha!$C$5:$C$788,MATCH(A13,Linha!$A$5:$A$788,0)),"-") | J13: 185 | K13: =IFERROR(INDEX(Linha!$D$5:$D$788,MATCH(A13,Linha!$A$5:$A$788,0))*1,0) | L13: =SUMIFS(Reservas!$K$5:$K$3669,Reservas!$A$5:$A$3669,A13) | M13: =J13-L13 | N13: 17.843 | O13: =J13*N13 | P13: =L13*N13 | Q13: 105.43377 | R13: =J13*Q13 | S13: =L13*Q13 | T13: =IF(J13=0,0,L13/J13) | U13: =IFERROR(INDEX(Paletes!$C$5:$C$393,MATCH(B13,Paletes!$A$5:$A$393,0)),"SEM CADASTRO") | V13: =IFERROR(INDEX(Paletes!$D$5:$D$393,MATCH(B13,Paletes!$A$5:$A$393,0)),0) | W13: =IF(V13=0,0,J13/V13) | X13: =IF(V13=0,0,MAX(M13,0)/V13)
A14: =B14&"."&IFERROR(MID(D14,FIND("(",D14)+1,FIND(")",D14)-FIND("(",D14)-1),"") -> 156.15500 | B14: 156 | C14: VOL CX MESA DE CABECEIRA C/03 GAV MAGGIORE NEW 0,700X0,390X0,171 | D14: (15500)FRASSINO/OFF WHITE | E14: 41606 | F14: UNIDADE DE COMPLEMENTOS | G14: VOLUME | H14: =IFERROR(INDEX(Linha!$B$5:$B$788,MATCH(A14,Linha!$A$5:$A$788,0)),"NÃO CADASTRADO") | I14: =IFERROR(INDEX(Linha!$C$5:$C$788,MATCH(A14,Linha!$A$5:$A$788,0)),"-") | J14: 29 | K14: =IFERROR(INDEX(Linha!$D$5:$D$788,MATCH(A14,Linha!$A$5:$A$788,0))*1,0) | L14: =SUMIFS(Reservas!$K$5:$K$3669,Reservas!$A$5:$A$3669,A14) | M14: =J14-L14 | N14: 17.843 | O14: =J14*N14 | P14: =L14*N14 | Q14: 76.317226 | R14: =J14*Q14 | S14: =L14*Q14 | T14: =IF(J14=0,0,L14/J14) | U14: =IFERROR(INDEX(Paletes!$C$5:$C$393,MATCH(B14,Paletes!$A$5:$A$393,0)),"SEM CADASTRO") | V14: =IFERROR(INDEX(Paletes!$D$5:$D$393,MATCH(B14,Paletes!$A$5:$A$393,0)),0) | W14: =IF(V14=0,0,J14/V14) | X14: =IF(V14=0,0,MAX(M14,0)/V14)
A15: =B15&"."&IFERROR(MID(D15,FIND("(",D15)+1,FIND(")",D15)-FIND("(",D15)-1),"") -> 73282.15764 | B15: 73282 | C15: VOL CX TAMPO COMODA 8GAV URBAN 2019 1,588X0,495X0,110 | D15: (15764)AMENDOA CLEAN | E15: 45137 | F15: UNIDADE DE COMPLEMENTOS | G15: VOLUME | H15: =IFERROR(INDEX(Linha!$B$5:$B$788,MATCH(A15,Linha!$A$5:$A$788,0)),"NÃO CADASTRADO") | I15: =IFERROR(INDEX(Linha!$C$5:$C$788,MATCH(A15,Linha!$A$5:$A$788,0)),"-") | J15: 332 | K15: =IFERROR(INDEX(Linha!$D$5:$D$788,MATCH(A15,Linha!$A$5:$A$788,0))*1,0) | L15: =SUMIFS(Reservas!$K$5:$K$3669,Reservas!$A$5:$A$3669,A15) | M15: =J15-L15 | N15: 41.05 | O15: =J15*N15 | P15: =L15*N15 | Q15: 197.2947 | R15: =J15*Q15 | S15: =L15*Q15 | T15: =IF(J15=0,0,L15/J15) | U15: =IFERROR(INDEX(Paletes!$C$5:$C$393,MATCH(B15,Paletes!$A$5:$A$393,0)),"SEM CADASTRO") | V15: =IFERROR(INDEX(Paletes!$D$5:$D$393,MATCH(B15,Paletes!$A$5:$A$393,0)),0) | W15: =IF(V15=0,0,J15/V15) | X15: =IF(V15=0,0,MAX(M15,0)/V15)
A16: =B16&"."&IFERROR(MID(D16,FIND("(",D16)+1,FIND(")",D16)-FIND("(",D16)-1),"") -> 73283.15562 | B16: 73283 | C16: VOL CX LATERAL COMODA 8GAV URBAN 2019 1,010X0,470X0,155 | D16: (15562)BRANCO | E16: 45138 | F16: UNIDADE DE COMPLEMENTOS | G16: VOLUME | H16: =IFERROR(INDEX(Linha!$B$5:$B$788,MATCH(A16,Linha!$A$5:$A$788,0)),"NÃO CADASTRADO") | I16: =IFERROR(INDEX(Linha!$C$5:$C$788,MATCH(A16,Linha!$A$5:$A$788,0)),"-") | J16: 306 | K16: =IFERROR(INDEX(Linha!$D$5:$D$788,MATCH(A16,Linha!$A$5:$A$788,0))*1,0) | L16: =SUMIFS(Reservas!$K$5:$K$3669,Reservas!$A$5:$A$3669,A16) | M16: =J16-L16 | N16: 30.95 | O16: =J16*N16 | P16: =L16*N16 | Q16: 138.36487 | R16: =J16*Q16 | S16: =L16*Q16 | T16: =IF(J16=0,0,L16/J16) | U16: =IFERROR(INDEX(Paletes!$C$5:$C$393,MATCH(B16,Paletes!$A$5:$A$393,0)),"SEM CADASTRO") | V16: =IFERROR(INDEX(Paletes!$D$5:$D$393,MATCH(B16,Paletes!$A$5:$A$393,0)),0) | W16: =IF(V16=0,0,J16/V16) | X16: =IF(V16=0,0,MAX(M16,0)/V16)
... A25: =B25&"."&IFERROR(MID(D25,FIND("(",D25)+1,FIND(")",D25)-FIND("(",D25)-1),"") -> 73550.16661 | B25: 73550 | C25: VOL CX ASSENTO/ENCOSTO CAD VENUS 2.3 C/2 | D25: (16661)LINHO CINZA CLARO | E25: 66401 | F25: UNIDADE DE SALAS | G25: VOLUME | H25: =IFERROR(INDEX(Linha!$B$5:$B$788,MATCH(A25,Linha!$A$5:$A$788,0)),"NÃO CADASTRADO") | I25: =IFERROR(INDEX(Linha!$C$5:$C$788,MATCH(A25,Linha!$A$5:$A$788,0)),"-") | J25: 0 | K25: =IFERROR(INDEX(Linha!$D$5:$D$788,MATCH(A25,Linha!$A$5:$A$788,0))*1,0) | L25: =SUMIFS(Reservas!$K$5:$K$3669,Reservas!$A$5:$A$3669,A25) | M25: =J25-L25 | N25: 11.358 | O25: =J25*N25 | P25: =L25*N25 | Q25: 92.955305 | R25: =J25*Q25 | S25: =L25*Q25 | T25: =IF(J25=0,0,L25/J25) | U25: =IFERROR(INDEX(Paletes!$C$5:$C$393,MATCH(B25,Paletes!$A$5:$A$393,0)),"SEM CADASTRO") | V25: =IFERROR(INDEX(Paletes!$D$5:$D$393,MATCH(B25,Paletes!$A$5:$A$393,0)),0) | W25: =IF(V25=0,0,J25/V25) | X25: =IF(V25=0,0,MAX(M25,0)/V25)
A26: =B26&"."&IFERROR(MID(D26,FIND("(",D26)+1,FIND(")",D26)-FIND("(",D26)-1),"") -> 95040.99258 | B26: 95040 | C26: VOL CX CADEIRA LAINI C/06 0,545X0,435X0,183 | D26: (99258)AMENDOA CLEAN | F26: UNIDADE DE SALAS | G26: VOLUME | H26: =IFERROR(INDEX(Linha!$B$5:$B$788,MATCH(A26,Linha!$A$5:$A$788,0)),"NÃO CADASTRADO") | I26: =IFERROR(INDEX(Linha!$C$5:$C$788,MATCH(A26,Linha!$A$5:$A$788,0)),"-") | J26: 0 | K26: =IFERROR(INDEX(Linha!$D$5:$D$788,MATCH(A26,Linha!$A$5:$A$788,0))*1,0) | L26: =SUMIFS(Reservas!$K$5:$K$3669,Reservas!$A$5:$A$3669,A26) | M26: =J26-L26 | N26: 20.962 | O26: =J26*N26 | P26: =L26*N26 | Q26: 112.36227 | R26: =J26*Q26 | S26: =L26*Q26 | T26: =IF(J26=0,0,L26/J26) | U26: =IFERROR(INDEX(Paletes!$C$5:$C$393,MATCH(B26,Paletes!$A$5:$A$393,0)),"SEM CADASTRO") | V26: =IFERROR(INDEX(Paletes!$D$5:$D$393,MATCH(B26,Paletes!$A$5:$A$393,0)),0) | W26: =IF(V26=0,0,J26/V26) | X26: =IF(V26=0,0,MAX(M26,0)/V26)
A27: =B27&"."&IFERROR(MID(D27,FIND("(",D27)+1,FIND(")",D27)-FIND("(",D27)-1),"") -> 86204.69459 | B27: 86204 | C27: VOL CX GR 2PTS QUADRIX/PAMPULHA TAMPO/MOLD 1,590X0,535X0,097 | D27: (69459)FRASSINO/OFF WHITE | E27: 99703 | F27: UNIDADE GUARDA ROUPAS | G27: VOLUME | H27: =IFERROR(INDEX(Linha!$B$5:$B$788,MATCH(A27,Linha!$A$5:$A$788,0)),"NÃO CADASTRADO") | I27: =IFERROR(INDEX(Linha!$C$5:$C$788,MATCH(A27,Linha!$A$5:$A$788,0)),"-") | J27: 25 | K27: =IFERROR(INDEX(Linha!$D$5:$D$788,MATCH(A27,Linha!$A$5:$A$788,0))*1,0) | L27: =SUMIFS(Reservas!$K$5:$K$3669,Reservas!$A$5:$A$3669,A27) | M27: =J27-L27 | N27: 30.663 | O27: =J27*N27 | P27: =L27*N27 | Q27: 147.00523 | R27: =J27*Q27 | S27: =L27*Q27 | T27: =IF(J27=0,0,L27/J27) | U27: =IFERROR(INDEX(Paletes!$C$5:$C$393,MATCH(B27,Paletes!$A$5:$A$393,0)),"SEM CADASTRO") | V27: =IFERROR(INDEX(Paletes!$D$5:$D$393,MATCH(B27,Paletes!$A$5:$A$393,0)),0) | W27: =IF(V27=0,0,J27/V27) | X27: =IF(V27=0,0,MAX(M27,0)/V27)
A28: =B28&"."&IFERROR(MID(D28,FIND("(",D28)+1,FIND(")",D28)-FIND("(",D28)-1),"") -> 73778. | B28: 73778 | C28: VOL CX ESPELHO C/1 ESP 1398X448X3 C/2 SUP 1,445X0,555X0,047 | E28: 39403 | F28: VIDRO/ESPELHO | G28: VOLUME | H28: =IFERROR(INDEX(Linha!$B$5:$B$788,MATCH(A28,Linha!$A$5:$A$788,0)),"NÃO CADASTRADO") | I28: =IFERROR(INDEX(Linha!$C$5:$C$788,MATCH(A28,Linha!$A$5:$A$788,0)),"-") | J28: 0 | K28: =IFERROR(INDEX(Linha!$D$5:$D$788,MATCH(A28,Linha!$A$5:$A$788,0))*1,0) | L28: =SUMIFS(Reservas!$K$5:$K$3669,Reservas!$A$5:$A$3669,A28) | M28: =J28-L28 | N28: 9.16 | O28: =J28*N28 | P28: =L28*N28 | Q28: 42.9189 | R28: =J28*Q28 | S28: =L28*Q28 | T28: =IF(J28=0,0,L28/J28) | U28: =IFERROR(INDEX(Paletes!$C$5:$C$393,MATCH(B28,Paletes!$A$5:$A$393,0)),"SEM CADASTRO") | V28: =IFERROR(INDEX(Paletes!$D$5:$D$393,MATCH(B28,Paletes!$A$5:$A$393,0)),0) | W28: =IF(V28=0,0,J28/V28) | X28: =IF(V28=0,0,MAX(M28,0)/V28)
A29: =B29&"."&IFERROR(MID(D29,FIND("(",D29)+1,FIND(")",D29)-FIND("(",D29)-1),"") -> 87565.93217 | B29: 87565 | C29: VOL CX KIT C/6 PUXADORES P/PORTA VIDRO GR SUAVITA 0,485X0,172X0,120 | D29: (93217)AMENDOA CLEAN | E29: 105325 | F29: UNIDADE GUARDA ROUPAS | G29: VOLUME | H29: =IFERROR(INDEX(Linha!$B$5:$B$788,MATCH(A29,Linha!$A$5:$A$788,0)),"NÃO CADASTRADO") | I29: =IFERROR(INDEX(Linha!$C$5:$C$788,MATCH(A29,Linha!$A$5:$A$788,0)),"-") | J29: 111 | K29: =IFERROR(INDEX(Linha!$D$5:$D$788,MATCH(A29,Linha!$A$5:$A$788,0))*1,0) | L29: =SUMIFS(Reservas!$K$5:$K$3669,Reservas!$A$5:$A$3669,A29) | M29: =J29-L29 | N29: 1.413 | O29: =J29*N29 | P29: =L29*N29 | Q29: 46.119645 | R29: =J29*Q29 | S29: =L29*Q29 | T29: =IF(J29=0,0,L29/J29) | U29: =IFERROR(INDEX(Paletes!$C$5:$C$393,MATCH(B29,Paletes!$A$5:$A$393,0)),"SEM CADASTRO") | V29: =IFERROR(INDEX(Paletes!$D$5:$D$393,MATCH(B29,Paletes!$A$5:$A$393,0)),0) | W29: =IF(V29=0,0,J29/V29) | X29: =IF(V29=0,0,MAX(M29,0)/V29)
A30: =B30&"."&IFERROR(MID(D30,FIND("(",D30)+1,FIND(")",D30)-FIND("(",D30)-1),"") -> 75871.65257 | B30: 75871 | C30: VOL CX GR 6 PTS LOOP 2024 COSTAS 2,270X0,940X0,010 | D30: (65257)BRANCO | E30: 91885 | F30: UNIDADE GUARDA ROUPAS | G30: VOLUME | H30: =IFERROR(INDEX(Linha!$B$5:$B$788,MATCH(A30,Linha!$A$5:$A$788,0)),"NÃO CADASTRADO") | I30: =IFERROR(INDEX(Linha!$C$5:$C$788,MATCH(A30,Linha!$A$5:$A$788,0)),"-") | J30: 84 | K30: =IFERROR(INDEX(Linha!$D$5:$D$788,MATCH(A30,Linha!$A$5:$A$788,0))*1,0) | L30: =SUMIFS(Reservas!$K$5:$K$3669,Reservas!$A$5:$A$3669,A30) | M30: =J30-L30 | N30: 17.062 | O30: =J30*N30 | P30: =L30*N30 | Q30: 44.210527 | R30: =J30*Q30 | S30: =L30*Q30 | T30: =IF(J30=0,0,L30/J30) | U30: =IFERROR(INDEX(Paletes!$C$5:$C$393,MATCH(B30,Paletes!$A$5:$A$393,0)),"SEM CADASTRO") | V30: =IFERROR(INDEX(Paletes!$D$5:$D$393,MATCH(B30,Paletes!$A$5:$A$393,0)),0) | W30: =IF(V30=0,0,J30/V30) | X30: =IF(V30=0,0,MAX(M30,0)/V30)
A31: =B31&"."&IFERROR(MID(D31,FIND("(",D31)+1,FIND(")",D31)-FIND("(",D31)-1),"") -> 74632.99862 | B31: 74632 | C31: VOL CX PES CAMA CASAL 1,40 REALI PLUS/SPECIALE 2023 EXP 1,430X0,260X0, | D31: (99862)AMENDOA CLEAN#C/LOGO | E31: 81398 | F31: UNIDADE DE COMPLEMENTOS | G31: VOLUME | H31: =IFERROR(INDEX(Linha!$B$5:$B$788,MATCH(A31,Linha!$A$5:$A$788,0)),"NÃO CADASTRADO") | I31: =IFERROR(INDEX(Linha!$C$5:$C$788,MATCH(A31,Linha!$A$5:$A$788,0)),"-") | J31: 0 | K31: =IFERROR(INDEX(Linha!$D$5:$D$788,MATCH(A31,Linha!$A$5:$A$788,0))*1,0) | L31: =SUMIFS(Reservas!$K$5:$K$3669,Reservas!$A$5:$A$3669,A31) | M31: =J31-L31 | N31: 18.78 | O31: =J31*N31 | P31: =L31*N31 | Q31: 116.55086 | R31: =J31*Q31 | S31: =L31*Q31 | T31: =IF(J31=0,0,L31/J31) | U31: =IFERROR(INDEX(Paletes!$C$5:$C$393,MATCH(B31,Paletes!$A$5:$A$393,0)),"SEM CADASTRO") | V31: =IFERROR(INDEX(Paletes!$D$5:$D$393,MATCH(B31,Paletes!$A$5:$A$393,0)),0) | W31: =IF(V31=0,0,J31/V31) | X31: =IF(V31=0,0,MAX(M31,0)/V31)
A32: =B32&"."&IFERROR(MID(D32,FIND("(",D32)+1,FIND(")",D32)-FIND("(",D32)-1),"") -> 84921.36180 | B32: 84921 | C32: VOL CX BARRA CAMA CASAL 1,60 LOOP/LEDER 2025 2,130X0,357X0,117 | D32: (36180)BRANCO | E32: 96440 | F32: UNIDADE DE COMPLEMENTOS | G32: VOLUME | H32: =IFERROR(INDEX(Linha!$B$5:$B$788,MATCH(A32,Linha!$A$5:$A$788,0)),"NÃO CADASTRADO") | I32: =IFERROR(INDEX(Linha!$C$5:$C$788,MATCH(A32,Linha!$A$5:$A$788,0)),"-") | J32: 15 | K32: =IFERROR(INDEX(Linha!$D$5:$D$788,MATCH(A32,Linha!$A$5:$A$788,0))*1,0) | L32: =SUMIFS(Reservas!$K$5:$K$3669,Reservas!$A$5:$A$3669,A32) | M32: =J32-L32 | N32: 41.73 | O32: =J32*N32 | P32: =L32*N32 | Q32: 206.9028 | R32: =J32*Q32 | S32: =L32*Q32 | T32: =IF(J32=0,0,L32/J32) | U32: =IFERROR(INDEX(Paletes!$C$5:$C$393,MATCH(B32,Paletes!$A$5:$A$393,0)),"SEM CADASTRO") | V32: =IFERROR(INDEX(Paletes!$D$5:$D$393,MATCH(B32,Paletes!$A$5:$A$393,0)),0) | W32: =IF(V32=0,0,J32/V32) | X32: =IF(V32=0,0,MAX(M32,0)/V32)
A33: =B33&"."&IFERROR(MID(D33,FIND("(",D33)+1,FIND(")",D33)-FIND("(",D33)-1),"") -> 85168.72896 | B33: 85168 | C33: VOL CX BASE MESA 1,70 LUAR 0,835X0,605X0,136 | D33: (72896)FRASSINO | E33: 96252 | F33: UNIDADE DE SALAS | G33: VOLUME | H33: =IFERROR(INDEX(Linha!$B$5:$B$788,MATCH(A33,Linha!$A$5:$A$788,0)),"NÃO CADASTRADO") | I33: =IFERROR(INDEX(Linha!$C$5:$C$788,MATCH(A33,Linha!$A$5:$A$788,0)),"-") | J33: 5 | K33: =IFERROR(INDEX(Linha!$D$5:$D$788,MATCH(A33,Linha!$A$5:$A$788,0))*1,0) | L33: =SUMIFS(Reservas!$K$5:$K$3669,Reservas!$A$5:$A$3669,A33) | M33: =J33-L33 | N33: 28.567 | O33: =J33*N33 | P33: =L33*N33 | Q33: 139.29433 | R33: =J33*Q33 | S33: =L33*Q33 | T33: =IF(J33=0,0,L33/J33) | U33: =IFERROR(INDEX(Paletes!$C$5:$C$393,MATCH(B33,Paletes!$A$5:$A$393,0)),"SEM CADASTRO") | V33: =IFERROR(INDEX(Paletes!$D$5:$D$393,MATCH(B33,Paletes!$A$5:$A$393,0)),0) | W33: =IF(V33=0,0,J33/V33) | X33: =IF(V33=0,0,MAX(M33,0)/V33)
A34: =B34&"."&IFERROR(MID(D34,FIND("(",D34)+1,FIND(")",D34)-FIND("(",D34)-1),"") -> 2280.31363 | B34: 2280 | C34: VOL CX GR 6 PTS LOOP PORTAS 2,400X0,436X0,103 | D34: (31363)SALVIA | E34: 86814 | F34: UNIDADE GUARDA ROUPAS | G34: VOLUME | H34: =IFERROR(INDEX(Linha!$B$5:$B$788,MATCH(A34,Linha!$A$5:$A$788,0)),"NÃO CADASTRADO") | I34: =IFERROR(INDEX(Linha!$C$5:$C$788,MATCH(A34,Linha!$A$5:$A$788,0)),"-") | J34: 0 | K34: =IFERROR(INDEX(Linha!$D$5:$D$788,MATCH(A34,Linha!$A$5:$A$788,0))*1,0) | L34: =SUMIFS(Reservas!$K$5:$K$3669,Reservas!$A$5:$A$3669,A34) | M34: =J34-L34 | N34: 59.943 | O34: =J34*N34 | P34: =L34*N34 | Q34: 219.2973 | R34: =J34*Q34 | S34: =L34*Q34 | T34: =IF(J34=0,0,L34/J34) | U34: =IFERROR(INDEX(Paletes!$C$5:$C$393,MATCH(B34,Paletes!$A$5:$A$393,0)),"SEM CADASTRO") | V34: =IFERROR(INDEX(Paletes!$D$5:$D$393,MATCH(B34,Paletes!$A$5:$A$393,0)),0) | W34: =IF(V34=0,0,J34/V34) | X34: =IF(V34=0,0,MAX(M34,0)/V34)
A35: =B35&"."&IFERROR(MID(D35,FIND("(",D35)+1,FIND(")",D35)-FIND("(",D35)-1),"") -> 73539.16556 | B35: 73539 | C35: VOL CX CADEIRA ATHENAS C/2 | D35: (16556)AMENDOA CLEAN | E35: 73511 | F35: UNIDADE DE SALAS | G35: VOLUME | H35: =IFERROR(INDEX(Linha!$B$5:$B$788,MATCH(A35,Linha!$A$5:$A$788,0)),"NÃO CADASTRADO") | I35: =IFERROR(INDEX(Linha!$C$5:$C$788,MATCH(A35,Linha!$A$5:$A$788,0)),"-") | J35: 0 | K35: =IFERROR(INDEX(Linha!$D$5:$D$788,MATCH(A35,Linha!$A$5:$A$788,0))*1,0) | L35: =SUMIFS(Reservas!$K$5:$K$3669,Reservas!$A$5:$A$3669,A35) | M35: =J35-L35 | N35: 12.675 | O35: =J35*N35 | P35: =L35*N35 | Q35: 70.966391 | R35: =J35*Q35 | S35: =L35*Q35 | T35: =IF(J35=0,0,L35/J35) | U35: =IFERROR(INDEX(Paletes!$C$5:$C$393,MATCH(B35,Paletes!$A$5:$A$393,0)),"SEM CADASTRO") | V35: =IFERROR(INDEX(Paletes!$D$5:$D$393,MATCH(B35,Paletes!$A$5:$A$393,0)),0) | W35: =IF(V35=0,0,J35/V35) | X35: =IF(V35=0,0,MAX(M35,0)/V35)
A36: =B36&"."&IFERROR(MID(D36,FIND("(",D36)+1,FIND(")",D36)-FIND("(",D36)-1),"") -> 73539.24026 | B36: 73539 | C36: VOL CX CADEIRA ATHENAS C/2 | D36: (24026)IMBUIA CLEAN | E36: 73511 | F36: UNIDADE DE SALAS | G36: VOLUME | H36: =IFERROR(INDEX(Linha!$B$5:$B$788,MATCH(A36,Linha!$A$5:$A$788,0)),"NÃO CADASTRADO") | I36: =IFERROR(INDEX(Linha!$C$5:$C$788,MATCH(A36,Linha!$A$5:$A$788,0)),"-") | J36: 1 | K36: =IFERROR(INDEX(Linha!$D$5:$D$788,MATCH(A36,Linha!$A$5:$A$788,0))*1,0) | L36: =SUMIFS(Reservas!$K$5:$K$3669,Reservas!$A$5:$A$3669,A36) | M36: =J36-L36 | N36: 12.675 | O36: =J36*N36 | P36: =L36*N36 | Q36: 70.966391 | R36: =J36*Q36 | S36: =L36*Q36 | T36: =IF(J36=0,0,L36/J36) | U36: =IFERROR(INDEX(Paletes!$C$5:$C$393,MATCH(B36,Paletes!$A$5:$A$393,0)),"SEM CADASTRO") | V36: =IFERROR(INDEX(Paletes!$D$5:$D$393,MATCH(B36,Paletes!$A$5:$A$393,0)),0) | W36: =IF(V36=0,0,J36/V36) | X36: =IF(V36=0,0,MAX(M36,0)/V36)
A37: =B37&"."&IFERROR(MID(D37,FIND("(",D37)+1,FIND(")",D37)-FIND("(",D37)-1),"") -> 73388.16470 | B37: 73388 | C37: VOL CX BASE MESA CELEBRARE 1,20 0,870X0,510X0,096 | D37: (16470)AMENDOA CLEAN | E37: 54394 | F37: UNIDADE DE SALAS | G37: VOLUME | H37: =IFERROR(INDEX(Linha!$B$5:$B$788,MATCH(A37,Linha!$A$5:$A$788,0)),"NÃO CADASTRADO") | I37: =IFERROR(INDEX(Linha!$C$5:$C$788,MATCH(A37,Linha!$A$5:$A$788,0)),"-") | J37: 313 | K37: =IFERROR(INDEX(Linha!$D$5:$D$788,MATCH(A37,Linha!$A$5:$A$788,0))*1,0) | L37: =SUMIFS(Reservas!$K$5:$K$3669,Reservas!$A$5:$A$3669,A37) | M37: =J37-L37 | N37: 15.795 | O37: =J37*N37 | P37: =L37*N37 | Q37: 86.281566 | R37: =J37*Q37 | S37: =L37*Q37 | T37: =IF(J37=0,0,L37/J37) | U37: =IFERROR(INDEX(Paletes!$C$5:$C$393,MATCH(B37,Paletes!$A$5:$A$393,0)),"SEM CADASTRO") | V37: =IFERROR(INDEX(Paletes!$D$5:$D$393,MATCH(B37,Paletes!$A$5:$A$393,0)),0) | W37: =IF(V37=0,0,J37/V37) | X37: =IF(V37=0,0,MAX(M37,0)/V37)
A38: =B38&"."&IFERROR(MID(D38,FIND("(",D38)+1,FIND(")",D38)-FIND("(",D38)-1),"") -> 2192.13154 | B38: 2192 | C38: VOL CX GR 6 PTS IMPERATORE/REALI/STIL KIT SAPAT 0,830X0,560X0,065 | D38: (13154)BRANCO | E38: 55521 | F38: UNIDADE GUARDA ROUPAS | G38: VOLUME | H38: =IFERROR(INDEX(Linha!$B$5:$B$788,MATCH(A38,Linha!$A$5:$A$788,0)),"NÃO CADASTRADO") | I38: =IFERROR(INDEX(Linha!$C$5:$C$788,MATCH(A38,Linha!$A$5:$A$788,0)),"-") | J38: 11 | K38: =IFERROR(INDEX(Linha!$D$5:$D$788,MATCH(A38,Linha!$A$5:$A$788,0))*1,0) | L38: =SUMIFS(Reservas!$K$5:$K$3669,Reservas!$A$5:$A$3669,A38) | M38: =J38-L38 | N38: 13.162 | O38: =J38*N38 | P38: =L38*N38 | Q38: 40.340933 | R38: =J38*Q38 | S38: =L38*Q38 | T38: =IF(J38=0,0,L38/J38) | U38: =IFERROR(INDEX(Paletes!$C$5:$C$393,MATCH(B38,Paletes!$A$5:$A$393,0)),"SEM CADASTRO") | V38: =IFERROR(INDEX(Paletes!$D$5:$D$393,MATCH(B38,Paletes!$A$5:$A$393,0)),0) | W38: =IF(V38=0,0,J38/V38) | X38: =IF(V38=0,0,MAX(M38,0)/V38)
A39: =B39&"."&IFERROR(MID(D39,FIND("(",D39)+1,FIND(")",D39)-FIND("(",D39)-1),"") -> 72643.16351 | B39: 72643 | C39: VOL CX GR 3/6 PTS OLLIE/CALEB/VINCE TAMPO/PRAT 2,745X0,550X0,103 | D39: (16351)AMENDOA CLEAN | E39: 87844 | F39: UNIDADE GUARDA ROUPAS | G39: VOLUME | H39: =IFERROR(INDEX(Linha!$B$5:$B$788,MATCH(A39,Linha!$A$5:$A$788,0)),"NÃO CADASTRADO") | I39: =IFERROR(INDEX(Linha!$C$5:$C$788,MATCH(A39,Linha!$A$5:$A$788,0)),"-") | J39: 0 | K39: =IFERROR(INDEX(Linha!$D$5:$D$788,MATCH(A39,Linha!$A$5:$A$788,0))*1,0) | L39: =SUMIFS(Reservas!$K$5:$K$3669,Reservas!$A$5:$A$3669,A39) | M39: =J39-L39 | N39: 62.361 | O39: =J39*N39 | P39: =L39*N39 | Q39: 184.46507 | R39: =J39*Q39 | S39: =L39*Q39 | T39: =IF(J39=0,0,L39/J39) | U39: =IFERROR(INDEX(Paletes!$C$5:$C$393,MATCH(B39,Paletes!$A$5:$A$393,0)),"SEM CADASTRO") | V39: =IFERROR(INDEX(Paletes!$D$5:$D$393,MATCH(B39,Paletes!$A$5:$A$393,0)),0) | W39: =IF(V39=0,0,J39/V39) | X39: =IF(V39=0,0,MAX(M39,0)/V39)
A40: =B40&"."&IFERROR(MID(D40,FIND("(",D40)+1,FIND(")",D40)-FIND("(",D40)-1),"") -> 72737.15527 | B40: 72737 | C40: VOL CX GR 3 PTS CALEB 2,40 COSTAS 2,245X0,806X0,015 | D40: (15527)AMENDOA CLEAN | E40: 88262 | F40: UNIDADE GUARDA ROUPAS | G40: VOLUME | H40: =IFERROR(INDEX(Linha!$B$5:$B$788,MATCH(A40,Linha!$A$5:$A$788,0)),"NÃO CADASTRADO") | I40: =IFERROR(INDEX(Linha!$C$5:$C$788,MATCH(A40,Linha!$A$5:$A$788,0)),"-") | J40: 0 | K40: =IFERROR(INDEX(Linha!$D$5:$D$788,MATCH(A40,Linha!$A$5:$A$788,0))*1,0) | L40: =SUMIFS(Reservas!$K$5:$K$3669,Reservas!$A$5:$A$3669,A40) | M40: =J40-L40 | N40: 14.04 | O40: =J40*N40 | P40: =L40*N40 | Q40: 50.401853 | R40: =J40*Q40 | S40: =L40*Q40 | T40: =IF(J40=0,0,L40/J40) | U40: =IFERROR(INDEX(Paletes!$C$5:$C$393,MATCH(B40,Paletes!$A$5:$A$393,0)),"SEM CADASTRO") | V40: =IFERROR(INDEX(Paletes!$D$5:$D$393,MATCH(B40,Paletes!$A$5:$A$393,0)),0) | W40: =IF(V40=0,0,J40/V40) | X40: =IF(V40=0,0,MAX(M40,0)/V40)
... A50: =B50&"."&IFERROR(MID(D50,FIND("(",D50)+1,FIND(")",D50)-FIND("(",D50)-1),"") -> 217.55179 | B50: 217 | C50: VOL CX ASSENTO/ENCOSTO CAD APOGEU/TESSERA C/20,585X0,370X0,430 | D50: (55179)COURO MORANO AVELA | E50: 32317 | F50: UNIDADE DE SALAS | G50: VOLUME | H50: =IFERROR(INDEX(Linha!$B$5:$B$788,MATCH(A50,Linha!$A$5:$A$788,0)),"NÃO CADASTRADO") | I50: =IFERROR(INDEX(Linha!$C$5:$C$788,MATCH(A50,Linha!$A$5:$A$788,0)),"-") | J50: 284 | K50: =IFERROR(INDEX(Linha!$D$5:$D$788,MATCH(A50,Linha!$A$5:$A$788,0))*1,0) | L50: =SUMIFS(Reservas!$K$5:$K$3669,Reservas!$A$5:$A$3669,A50) | M50: =J50-L50 | N50: 11.51 | O50: =J50*N50 | P50: =L50*N50 | Q50: 67.672951 | R50: =J50*Q50 | S50: =L50*Q50 | T50: =IF(J50=0,0,L50/J50) | U50: =IFERROR(INDEX(Paletes!$C$5:$C$393,MATCH(B50,Paletes!$A$5:$A$393,0)),"SEM CADASTRO") | V50: =IFERROR(INDEX(Paletes!$D$5:$D$393,MATCH(B50,Paletes!$A$5:$A$393,0)),0) | W50: =IF(V50=0,0,J50/V50) | X50: =IF(V50=0,0,MAX(M50,0)/V50)
A51: =B51&"."&IFERROR(MID(D51,FIND("(",D51)+1,FIND(")",D51)-FIND("(",D51)-1),"") -> 87626.93315 | B51: 87626 | C51: VOL CX ASSENTO/ENCOSTO CAD LAINI C/2 0,585X0,370X0,430 | D51: (93315)LINHO RINZAI BEGE | F51: UNIDADE DE SALAS | G51: VOLUME | H51: =IFERROR(INDEX(Linha!$B$5:$B$788,MATCH(A51,Linha!$A$5:$A$788,0)),"NÃO CADASTRADO") | I51: =IFERROR(INDEX(Linha!$C$5:$C$788,MATCH(A51,Linha!$A$5:$A$788,0)),"-") | J51: 451 | K51: =IFERROR(INDEX(Linha!$D$5:$D$788,MATCH(A51,Linha!$A$5:$A$788,0))*1,0) | L51: =SUMIFS(Reservas!$K$5:$K$3669,Reservas!$A$5:$A$3669,A51) | M51: =J51-L51 | N51: 11.51 | O51: =J51*N51 | P51: =L51*N51 | Q51: 56.100989 | R51: =J51*Q51 | S51: =L51*Q51 | T51: =IF(J51=0,0,L51/J51) | U51: =IFERROR(INDEX(Paletes!$C$5:$C$393,MATCH(B51,Paletes!$A$5:$A$393,0)),"SEM CADASTRO") | V51: =IFERROR(INDEX(Paletes!$D$5:$D$393,MATCH(B51,Paletes!$A$5:$A$393,0)),0) | W51: =IF(V51=0,0,J51/V51) | X51: =IF(V51=0,0,MAX(M51,0)/V51)
A52: =B52&"."&IFERROR(MID(D52,FIND("(",D52)+1,FIND(")",D52)-FIND("(",D52)-1),"") -> 87025.90076 | B52: 87025 | C52: VOL CX BARRA CAMA CASAL 1,80 LOOP/LEDER 2025 2,130X0,357X0,117 | D52: (90076)AMENDOA CLEAN#C/LOGO | E52: 102955 | F52: UNIDADE DE COMPLEMENTOS | G52: VOLUME | H52: =IFERROR(INDEX(Linha!$B$5:$B$788,MATCH(A52,Linha!$A$5:$A$788,0)),"NÃO CADASTRADO") | I52: =IFERROR(INDEX(Linha!$C$5:$C$788,MATCH(A52,Linha!$A$5:$A$788,0)),"-") | J52: 2 | K52: =IFERROR(INDEX(Linha!$D$5:$D$788,MATCH(A52,Linha!$A$5:$A$788,0))*1,0) | L52: =SUMIFS(Reservas!$K$5:$K$3669,Reservas!$A$5:$A$3669,A52) | M52: =J52-L52 | N52: 39 | O52: =J52*N52 | P52: =L52*N52 | Q52: 206.72334 | R52: =J52*Q52 | S52: =L52*Q52 | T52: =IF(J52=0,0,L52/J52) | U52: =IFERROR(INDEX(Paletes!$C$5:$C$393,MATCH(B52,Paletes!$A$5:$A$393,0)),"SEM CADASTRO") | V52: =IFERROR(INDEX(Paletes!$D$5:$D$393,MATCH(B52,Paletes!$A$5:$A$393,0)),0) | W52: =IF(V52=0,0,J52/V52) | X52: =IF(V52=0,0,MAX(M52,0)/V52)
A53: =B53&"."&IFERROR(MID(D53,FIND("(",D53)+1,FIND(")",D53)-FIND("(",D53)-1),"") -> 87121.90710 | B53: 87121 | C53: VOL CX TAMPO GR 04 PTS LOOP 1,880X0,520X0,105 | D53: (90710)AMENDOA CLEAN | E53: 104474 | F53: UNIDADE GUARDA ROUPAS | G53: VOLUME | H53: =IFERROR(INDEX(Linha!$B$5:$B$788,MATCH(A53,Linha!$A$5:$A$788,0)),"NÃO CADASTRADO") | I53: =IFERROR(INDEX(Linha!$C$5:$C$788,MATCH(A53,Linha!$A$5:$A$788,0)),"-") | J53: 315 | K53: =IFERROR(INDEX(Linha!$D$5:$D$788,MATCH(A53,Linha!$A$5:$A$788,0))*1,0) | L53: =SUMIFS(Reservas!$K$5:$K$3669,Reservas!$A$5:$A$3669,A53) | M53: =J53-L53 | N53: 49.725 | O53: =J53*N53 | P53: =L53*N53 | Q53: 172.21274 | R53: =J53*Q53 | S53: =L53*Q53 | T53: =IF(J53=0,0,L53/J53) | U53: =IFERROR(INDEX(Paletes!$C$5:$C$393,MATCH(B53,Paletes!$A$5:$A$393,0)),"SEM CADASTRO") | V53: =IFERROR(INDEX(Paletes!$D$5:$D$393,MATCH(B53,Paletes!$A$5:$A$393,0)),0) | W53: =IF(V53=0,0,J53/V53) | X53: =IF(V53=0,0,MAX(M53,0)/V53)
A54: =B54&"."&IFERROR(MID(D54,FIND("(",D54)+1,FIND(")",D54)-FIND("(",D54)-1),"") -> 87130.90734 | B54: 87130 | C54: VOL CX JOGO DE PES LOPAS C/06 GR LOOP 0,282X0,140X0,069 | D54: (90734)AMENDOA CLEAN | E54: 104501 | F54: UNIDADE GUARDA ROUPAS | G54: VOLUME | H54: =IFERROR(INDEX(Linha!$B$5:$B$788,MATCH(A54,Linha!$A$5:$A$788,0)),"NÃO CADASTRADO") | I54: =IFERROR(INDEX(Linha!$C$5:$C$788,MATCH(A54,Linha!$A$5:$A$788,0)),"-") | J54: 155 | K54: =IFERROR(INDEX(Linha!$D$5:$D$788,MATCH(A54,Linha!$A$5:$A$788,0))*1,0) | L54: =SUMIFS(Reservas!$K$5:$K$3669,Reservas!$A$5:$A$3669,A54) | M54: =J54-L54 | N54: 0.546 | O54: =J54*N54 | P54: =L54*N54 | Q54: 6.148682 | R54: =J54*Q54 | S54: =L54*Q54 | T54: =IF(J54=0,0,L54/J54) | U54: =IFERROR(INDEX(Paletes!$C$5:$C$393,MATCH(B54,Paletes!$A$5:$A$393,0)),"SEM CADASTRO") | V54: =IFERROR(INDEX(Paletes!$D$5:$D$393,MATCH(B54,Paletes!$A$5:$A$393,0)),0) | W54: =IF(V54=0,0,J54/V54) | X54: =IF(V54=0,0,MAX(M54,0)/V54)
A55: =B55&"."&IFERROR(MID(D55,FIND("(",D55)+1,FIND(")",D55)-FIND("(",D55)-1),"") -> 87140.90813 | B55: 87140 | C55: VOL CX GR 03PTS ATLAS PORTAS/COSTAS 1,920X0,555X0,095 | D55: (90813)AMENDOA CLEAN/OFF WH | F55: UNIDADE GUARDA ROUPAS | G55: VOLUME | H55: =IFERROR(INDEX(Linha!$B$5:$B$788,MATCH(A55,Linha!$A$5:$A$788,0)),"NÃO CADASTRADO") | I55: =IFERROR(INDEX(Linha!$C$5:$C$788,MATCH(A55,Linha!$A$5:$A$788,0)),"-") | J55: 22 | K55: =IFERROR(INDEX(Linha!$D$5:$D$788,MATCH(A55,Linha!$A$5:$A$788,0))*1,0) | L55: =SUMIFS(Reservas!$K$5:$K$3669,Reservas!$A$5:$A$3669,A55) | M55: =J55-L55 | N55: 46.312 | O55: =J55*N55 | P55: =L55*N55 | Q55: 126.0522 | R55: =J55*Q55 | S55: =L55*Q55 | T55: =IF(J55=0,0,L55/J55) | U55: =IFERROR(INDEX(Paletes!$C$5:$C$393,MATCH(B55,Paletes!$A$5:$A$393,0)),"SEM CADASTRO") | V55: =IFERROR(INDEX(Paletes!$D$5:$D$393,MATCH(B55,Paletes!$A$5:$A$393,0)),0) | W55: =IF(V55=0,0,J55/V55) | X55: =IF(V55=0,0,MAX(M55,0)/V55)
A56: =B56&"."&IFERROR(MID(D56,FIND("(",D56)+1,FIND(")",D56)-FIND("(",D56)-1),"") -> 87140.90814 | B56: 87140 | C56: VOL CX GR 03PTS ATLAS PORTAS/COSTAS 1,920X0,555X0,095 | D56: (90814)BRANCO | F56: UNIDADE GUARDA ROUPAS | G56: VOLUME | H56: =IFERROR(INDEX(Linha!$B$5:$B$788,MATCH(A56,Linha!$A$5:$A$788,0)),"NÃO CADASTRADO") | I56: =IFERROR(INDEX(Linha!$C$5:$C$788,MATCH(A56,Linha!$A$5:$A$788,0)),"-") | J56: 50 | K56: =IFERROR(INDEX(Linha!$D$5:$D$788,MATCH(A56,Linha!$A$5:$A$788,0))*1,0) | L56: =SUMIFS(Reservas!$K$5:$K$3669,Reservas!$A$5:$A$3669,A56) | M56: =J56-L56 | N56: 46.312 | O56: =J56*N56 | P56: =L56*N56 | Q56: 165.66808 | R56: =J56*Q56 | S56: =L56*Q56 | T56: =IF(J56=0,0,L56/J56) | U56: =IFERROR(INDEX(Paletes!$C$5:$C$393,MATCH(B56,Paletes!$A$5:$A$393,0)),"SEM CADASTRO") | V56: =IFERROR(INDEX(Paletes!$D$5:$D$393,MATCH(B56,Paletes!$A$5:$A$393,0)),0) | W56: =IF(V56=0,0,J56/V56) | X56: =IF(V56=0,0,MAX(M56,0)/V56)
A57: =B57&"."&IFERROR(MID(D57,FIND("(",D57)+1,FIND(")",D57)-FIND("(",D57)-1),"") -> 87469.91611 | B57: 87469 | C57: VOL CX GR 8PTS SERENATA PORTAS 1,950X0,305X0,130 | D57: (91611)AMENDOA CLEAN | E57: 104712 | F57: UNIDADE GUARDA ROUPAS | G57: VOLUME | H57: =IFERROR(INDEX(Linha!$B$5:$B$788,MATCH(A57,Linha!$A$5:$A$788,0)),"NÃO CADASTRADO") | I57: =IFERROR(INDEX(Linha!$C$5:$C$788,MATCH(A57,Linha!$A$5:$A$788,0)),"-") | J57: 359 | K57: =IFERROR(INDEX(Linha!$D$5:$D$788,MATCH(A57,Linha!$A$5:$A$788,0))*1,0) | L57: =SUMIFS(Reservas!$K$5:$K$3669,Reservas!$A$5:$A$3669,A57) | M57: =J57-L57 | N57: 46.848 | O57: =J57*N57 | P57: =L57*N57 | Q57: 162.35259 | R57: =J57*Q57 | S57: =L57*Q57 | T57: =IF(J57=0,0,L57/J57) | U57: =IFERROR(INDEX(Paletes!$C$5:$C$393,MATCH(B57,Paletes!$A$5:$A$393,0)),"SEM CADASTRO") | V57: =IFERROR(INDEX(Paletes!$D$5:$D$393,MATCH(B57,Paletes!$A$5:$A$393,0)),0) | W57: =IF(V57=0,0,J57/V57) | X57: =IF(V57=0,0,MAX(M57,0)/V57)
...

Sheet Reservas
A1: RESERVAS — SALDO DE ITENS COM RESERVA
A2: 3665 linhas importadas • 02/10/2026, 13:56:55
A4: CHAVE | B4: ALMOXARIFADO | C4: COD ITEM | D4: DESCRICAO ITEM | E4: MASCARA | F4: CLASS | G4: PESO BRT | H4: CUSTO MEDIO | I4: VALOR ESTOQUE | J4: SALDO ATUAL | K4: QTD RESERVADA | L4: QTD DISPONIVEL
A5: =C5&"."&IFERROR(MID(E5,FIND("(",E5)+1,FIND(")",E5)-FIND("(",E5)-1),"") | B5: 11 - EXPEDIÇÃO WMS | C5: 100336 | D5: VOL CX PENTEADEIRA LIVIA - VOL 1 S/LED 1,260X0,685X0,105 | E5: BRANCO ID: (118082) | F5: UNIDADE DE COMPLEMENTOS | G5: 39 | H5: 249.101 | I5: 12455.062 | J5: 50 | K5: 30 | L5: 20
A6: =C6&"."&IFERROR(MID(E6,FIND("(",E6)+1,FIND(")",E6)-FIND("(",E6)-1),"") | B6: 11 - EXPEDIÇÃO WMS | C6: 101 | D6: VOL CX GR 6 PTS ZEUS 2021 LAT/TAMPO 2,122X0,460X0,125 | E6: BRANCO ID: (10338) | F6: UNIDADE GUARDA ROUPAS | G6: 68.5 | H6: 202.467 | I6: 3441.947 | J6: 17 | K6: 17 | L6: 0
A7: =C7&"."&IFERROR(MID(E7,FIND("(",E7)+1,FIND(")",E7)-FIND("(",E7)-1),"") | B7: 11 - EXPEDIÇÃO WMS | C7: 101 | D7: VOL CX GR 6 PTS ZEUS 2021 LAT/TAMPO 2,122X0,460X0,125 | E7: AMENDOA CLEAN ID: (4514) | F7: UNIDADE GUARDA ROUPAS | G7: 68.5 | H7: 214.067 | I7: 62721.501 | J7: 293 | K7: 248 | L7: 45
A8: =C8&"."&IFERROR(MID(E8,FIND("(",E8)+1,FIND(")",E8)-FIND("(",E8)-1),"") | B8: 11 - EXPEDIÇÃO WMS | C8: 102 | D8: VOL CX GR 6 PTS ZEUS PLUS PTS/COSTAS 1,950X0,600X0,067 | E8: AMENDOA CLEAN/OFF WH ID: (12222) | F8: UNIDADE GUARDA ROUPAS | G8: 39.6 | H8: 140.904 | I8: 31985.188 | J8: 227 | K8: 132 | L8: 95
A9: =C9&"."&IFERROR(MID(E9,FIND("(",E9)+1,FIND(")",E9)-FIND("(",E9)-1),"") | B9: 11 - EXPEDIÇÃO WMS | C9: 102 | D9: VOL CX GR 6 PTS ZEUS PLUS PTS/COSTAS 1,950X0,600X0,067 | E9: BRANCO ID: (12220) | F9: UNIDADE GUARDA ROUPAS | G9: 39.6 | H9: 149.652 | I9: 10924.587 | J9: 73 | K9: 18 | L9: 55
A10: =C10&"."&IFERROR(MID(E10,FIND("(",E10)+1,FIND(")",E10)-FIND("(",E10)-1),"") | B10: 11 - EXPEDIÇÃO WMS | C10: 102 | D10: VOL CX GR 6 PTS ZEUS PLUS PTS/COSTAS 1,950X0,600X0,067 | E10: AMENDOA CLEAN ID: (12218) | F10: UNIDADE GUARDA ROUPAS | G10: 39.6 | H10: 143.741 | I10: 28748.152 | J10: 200 | K10: 115 | L10: 85
A11: =C11&"."&IFERROR(MID(E11,FIND("(",E11)+1,FIND(")",E11)-FIND("(",E11)-1),"") | B11: 11 - EXPEDIÇÃO WMS | C11: 102 | D11: VOL CX GR 6 PTS ZEUS PLUS PTS/COSTAS 1,950X0,600X0,067 | E11: IMBUIA CLEAN ID: (64910) | F11: UNIDADE GUARDA ROUPAS | G11: 39.6 | H11: 126.24 | I11: 126.24 | J11: 1 | K11: 0 | L11: 1
A12: =C12&"."&IFERROR(MID(E12,FIND("(",E12)+1,FIND(")",E12)-FIND("(",E12)-1),"") | B12: 11 - EXPEDIÇÃO WMS | C12: 103 | D12: PRATELEIRA INFERIOR GR 4/6 PTS ZEUS 575X330X12 MDP | E12: AMENDOA CLEAN ID: (42272) | F12: UNIDADE GUARDA ROUPAS | G12: 1.56 | H12: 7.507 | I12: 30.026 | J12: 4 | K12: 0 | L12: 4
A13: =C13&"."&IFERROR(MID(E13,FIND("(",E13)+1,FIND(")",E13)-FIND("(",E13)-1),"") | B13: 11 - EXPEDIÇÃO WMS | C13: 103 | D13: PRATELEIRA INFERIOR GR 4/6 PTS ZEUS 575X330X12 MDP | E13: FRASSINO ID: (42278) | F13: UNIDADE GUARDA ROUPAS | G13: 1.56 | H13: 4.97 | I13: 9.94 | J13: 2 | K13: 0 | L13: 2
A14: =C14&"."&IFERROR(MID(E14,FIND("(",E14)+1,FIND(")",E14)-FIND("(",E14)-1),"") | B14: 11 - EXPEDIÇÃO WMS | C14: 103 | D14: PRATELEIRA INFERIOR GR 4/6 PTS ZEUS 575X330X12 MDP | E14: BRANCO ID: (42274) | F14: UNIDADE GUARDA ROUPAS | G14: 1.56 | H14: 2.775 | I14: 24.976 | J14: 9 | K14: 0 | L14: 9
A15: =C15&"."&IFERROR(MID(E15,FIND("(",E15)+1,FIND(")",E15)-FIND("(",E15)-1),"") | B15: 11 - EXPEDIÇÃO WMS | C15: 104 | D15: PRATELEIRA GR 4/6 PTS ZEUS/VIRGO/EASY P2L 575X330X12 MDP | E15: AMENDOA CLEAN ID: (41337) | F15: UNIDADE GUARDA ROUPAS | G15: 1.56 | H15: 9.542 | I15: 19.085 | J15: 2 | K15: 1 | L15: 1
A16: =C16&"."&IFERROR(MID(E16,FIND("(",E16)+1,FIND(")",E16)-FIND("(",E16)-1),"") | B16: 11 - EXPEDIÇÃO WMS | C16: 104 | D16: PRATELEIRA GR 4/6 PTS ZEUS/VIRGO/EASY P2L 575X330X12 MDP | E16: BRANCO ID: (41339) | F16: UNIDADE GUARDA ROUPAS | G16: 1.56 | H16: 4.495 | I16: 22.476 | J16: 5 | K16: 0 | L16: 5
... A3669: =C3669&"."&IFERROR(MID(E3669,FIND("(",E3669)+1,FIND(")",E3669)-FIND("(",E3669)-1),"") | B3669: 11 - EXPEDIÇÃO WMS | C3669: 99613 | D3669: PARTE PC PORTA GRAN GR 4/6/8PTS ZEUS/VIR/EASY SLIM 1877X290X15 MDP | E3669: FRASSINO ID: (112419) | F3669: UNIDADE GUARDA ROUPAS | G3669: 5.77 | H3669: 18.028 | I3669: 18.028 | J3669: 1 | K3669: 0 | L3669: 1

Sheet Linha
A1: CADASTRO EM LINHA x FORA DE LINHA
A2: Tabela fixa de referência — edite aqui para reclassificar itens
A4: CHAVE | B4: SITUAÇÃO | C4: ORIGEM | D4: SALDO FULL
A5: 101.10338 | B5: EM LINHA | C5: NAO INFORMADO | D5: 0
A6: 101.4514 | B6: EM LINHA | C6: NAO INFORMADO | D6: 0
A7: 102.12218 | B7: EM LINHA | C7: NAO INFORMADO | D7: 0
A8: 102.1222 | B8: EM LINHA | C8: NAO INFORMADO | D8: 0
A9: 102.12222 | B9: EM LINHA | C9: NAO INFORMADO | D9: 0
A10: 102.6491 | B10: EM LINHA | C10: NAO INFORMADO | D10: 0
A11: 153.0 | B11: EM LINHA | C11: NAO INFORMADO | D11: 0
A12: 154.16634 | B12: EM LINHA | C12: NAO INFORMADO | D12: 0
A13: 154.16635 | B13: EM LINHA | C13: NAO INFORMADO | D13: 0
A14: 156.15496 | B14: EM LINHA | C14: NAO INFORMADO | D14: 0
A15: 156.15497 | B15: EM LINHA | C15: NAO INFORMADO | D15: 0
A16: 156.15498 | B16: EM LINHA | C16: NAO INFORMADO | D16: 0
... A788: 86383.70245 | B788: FORA DE LINHA | C788: SO GERSON | D788: 10

Sheet Paletes
A1: PALETE DOS ITENS
A2: Tabela fixa de referência — UND/PALETE extraída do texto do forro
A4: COD ITEM | B4: DESC TÉCNICA | C4: PALLET FORRO | D4: UND / PALETE
A5: 217 | B5: VOL CX ASSENTO/ENCOSTO CAD APOGEU/TESSERA C/20,585X0,370X0,430 | C5: TAM P= 4 PILHAS C/2UND= 8UND | D5: 8
A6: 73534 | B6: VOL CX ASSENTO/ENCOSTO CAD ASTRID C/2 | C6: PALETE P: 11 UND | D6: 11
A7: 73540 | B7: VOL CX ASSENTO/ENCOSTO CAD ATHENAS C/20,455X0,455X0,125 | C7: TAM P= 5 PILHAS C/10UND= 50UND | D7: 50
A8: 87626 | B8: VOL CX ASSENTO/ENCOSTO CAD LAINI C/2 0,585X0,370X0,430 | C8: TAM P= 3 PILHAS C/3UND= 9UND | D8: 9
A9: 73547 | B9: VOL CX ASSENTO/ENCOSTO CAD RAYLA C/20,590X0,375X0,432 | C9: TAM P= 4 PILHAS C/3UND= 12UND | D9: 12
A10: 85366 | B10: VOL CX ASSENTO/ENCOSTO CADEIRA LUAR C/2 0,615X0,455X0,460 | C10: TAM P= 4 PILHAS C/2UND= 8UND | D10: 8
A11: 2161 | B11: VOL CX BARRA ATHENAS CASAL 2022 1,975X0,340X0,080 | C11: TAM G= 3 PILHAS C/16UND= 48UND | D11: 48
A12: 73141 | B12: VOL CX BARRA ATHENAS SOLT 0,90 2022 1,975X0,395X0,045 | C12: TAM G= 3 PILHAS C/21UND= 63UND | D12: 63
A13: 74551 | B13: VOL CX BARRA C/LED BELICHE 0,90 OLGA 2,398X0,383X0,125 | C13: TAM G= 3 PILHAS C/8UND= 24UND | D13: 24
A14: 84938 | B14: VOL CX BARRA CAMA 0,90 LOOP 2025 2,018X0,357X0,100 | C14: TAM G= 3 PILHAS C/10UND= 30UND | D14: 30
A15: 84980 | B15: VOL CX BARRA CAMA 0,90 LOOP 2025 EXP 2,018X0,357X0,100 | C15: PALETE G=38UN | D15: 0
A16: 85651 | B16: VOL CX BARRA CAMA 1,60 FREETOWN 2025 2,075X0,345X0,110 | C16: TAM G= 3 PILHAS C/11UND= 33UND | D16: 33
... A393: 84877 | B393: VOL CX LAT GR 06 PTS LEDER 2025 2,375X0,550X0,078 | C393: PALETE G=24UN | D393: 0
